<?xml version="1.0" ?>
<!-- =================================================================================== -->
<!-- |    This document was autogenerated by xacro from lab03.main.urdf                | -->
<!-- |    EDITING THIS FILE BY HAND IS NOT RECOMMENDED                                 | -->
<!-- =================================================================================== -->
<robot name="lab03" xmlns:xacro="http://www.ros.org/wiki/xacro">
  <material name="blue">
    <color rgba="0 0 0.8 1"/>
  </material>
  <material name="green">
    <color rgba="0 0.8 0 1"/>
  </material>
  <material name="red">
    <color rgba="0.8 0 0 1"/>
  </material>
  <link name="base_link"/>
  <link name="robot_chassis">
    <visual>
      <geometry>
        <cylinder length="0.075" radius="0.2"/>
      </geometry>
      <material name="red"/>
    </visual>
  </link>
  <joint name="chassis_joint" type="fixed">
    <parent link="base_link"/>
    <child link="robot_chassis"/>
    <origin xyz="0 0 0.5"/>
  </joint>
  <link name="left_wheel">
    <visual>
      <geometry>
        <cylinder length="0.05" radius="0.075"/>
      </geometry>
      <origin rpy="1.57075 0 0"/>
      <material name="green"/>
    </visual>
  </link>
  <joint name="left_wheel_joint" type="continuous">
    <parent link="robot_chassis"/>
    <child link="left_wheel"/>
    <origin xyz="0 0.15 0"/>
    <axis xyz="0 1 0"/>
  </joint>
  <link name="right_wheel">
    <visual>
      <geometry>
        <cylinder length="0.05" radius="0.075"/>
      </geometry>
      <origin rpy="1.57075 0 0"/>
      <material name="blue"/>
    </visual>
  </link>
  <joint name="right_wheel_joint" type="continuous">
    <parent link="robot_chassis"/>
    <child link="right_wheel"/>
    <origin xyz="0 -0.15 0"/>
    <axis xyz="0 1 0"/>
  </joint>
</robot>

